<?xml version='1.0' encoding='utf-8'?>
<robot xmlns:xacro="http://ros.org/wiki/xacro"><xacro:macro name="abb_irb2400" params="prefix"><link name="${prefix}base_link"><visual><origin rpy="0 0 0" xyz="0 0 0" /><geometry><mesh filename="package://vc_ros_tutorials/meshes/abb_irb2400/visual/base_link.stl" /></geometry></visual><collision><geometry><mesh filename="package://vc_ros_tutorials/meshes/abb_irb2400/visual/base_link.stl" /></geometry></collision></link><link name="${prefix}link1"><visual><origin rpy="0 0 0" xyz="0 0 0" /><geometry><mesh filename="package://vc_ros_tutorials/meshes/abb_irb2400/visual/link1.stl" /></geometry></visual><collision><geometry><mesh filename="package://vc_ros_tutorials/meshes/abb_irb2400/visual/link1.stl" /></geometry></collision></link><link name="${prefix}link2"><visual><origin rpy="0 0 0" xyz="0 0 0" /><geometry><mesh filename="package://vc_ros_tutorials/meshes/abb_irb2400/visual/link2.stl" /></geometry></visual><collision><geometry><mesh filename="package://vc_ros_tutorials/meshes/abb_irb2400/visual/link2.stl" /></geometry></collision></link><link name="${prefix}link3"><visual><origin rpy="0 0 0" xyz="0 0 0" /><geometry><mesh filename="package://vc_ros_tutorials/meshes/abb_irb2400/visual/link3.stl" /></geometry></visual><collision><geometry><mesh filename="package://vc_ros_tutorials/meshes/abb_irb2400/visual/link3.stl" /></geometry></collision></link><link name="${prefix}link4"><visual><origin rpy="0 0 0" xyz="0 0 0" /><geometry><mesh filename="package://vc_ros_tutorials/meshes/abb_irb2400/visual/link4.stl" /></geometry></visual><collision><geometry><mesh filename="package://vc_ros_tutorials/meshes/abb_irb2400/visual/link4.stl" /></geometry></collision></link><link name="${prefix}link5"><visual><origin rpy="0 0 0" xyz="0 0 0" /><geometry><mesh filename="package://vc_ros_tutorials/meshes/abb_irb2400/visual/link5.stl" /></geometry></visual><collision><geometry><mesh filename="package://vc_ros_tutorials/meshes/abb_irb2400/visual/link5.stl" /></geometry></collision></link><link name="${prefix}link6"><visual><origin rpy="0 0 0" xyz="0 0 0" /><geometry><mesh filename="package://vc_ros_tutorials/meshes/abb_irb2400/visual/link6.stl" /></geometry></visual><collision><geometry><mesh filename="package://vc_ros_tutorials/meshes/abb_irb2400/visual/link6.stl" /></geometry></collision></link><joint name="${prefix}Axis1" type="revolute"><origin rpy="0.0 -0.0 0.0" xyz="0.0 0.0 0.0" /><parent link="${prefix}base_link" /><child link="${prefix}link1" /><axis xyz="0 0 1" /><limit effort="0" lower="-3.14" upper="3.14" velocity="12.0" /></joint><joint name="${prefix}Axis2" type="revolute"><origin rpy="0.0 -0.0 0.0" xyz="0.1 0.0 0.615" /><parent link="${prefix}link1" /><child link="${prefix}link2" /><axis xyz="0 1 0" /><limit effort="0" lower="-1.13388888889" upper="1.04666666667" velocity="12.0" /></joint><joint name="${prefix}Axis3" type="revolute"><origin rpy="0.0 1.57 0.0" xyz="0.0 0.0 0.705" /><parent link="${prefix}link2" /><child link="${prefix}link3" /><axis xyz="0 1 0" /><limit effort="0" lower="-1.04666666667" upper="1.13388888889" velocity="12.0" /></joint><joint name="${prefix}Axis4" type="revolute"><origin rpy="0.0 -0.0 0.0" xyz="-0.135 0.0 0.755" /><parent link="${prefix}link3" /><child link="${prefix}link4" /><axis xyz="0 0 1" /><limit effort="0" lower="-3.48888888889" upper="3.48888888889" velocity="28.0" /></joint><joint name="${prefix}Axis5" type="revolute"><origin rpy="-1.57 -0.0 0.0" xyz="0.0 0.0 0.0" /><parent link="${prefix}link4" /><child link="${prefix}link5" /><axis xyz="0 0 1" /><limit effort="0" lower="-2.09333333333" upper="2.09333333333" velocity="28.0" /></joint><joint name="${prefix}Axis6" type="revolute"><origin rpy="1.57 -0.0 0.0" xyz="0.0 -0.085 5.20474889638e-18" /><parent link="${prefix}link5" /><child link="${prefix}link6" /><axis xyz="0 0 1" /><limit effort="0" lower="-6.97777777778" upper="6.97777777778" velocity="28.0" /></joint></xacro:macro></robot>